Workbook

Sheet SAM_73
A2: Turkey 2023 social accounting matrix
A3: Thousand TRY; rows receive and columns share. 64 sectors + 9 accounts; separate PTAX and CTAX.
A5: Account | B5: S00 | C5: S01 | D5: S02 | E5: S03 | F5: S04 | G5: S05 | H5: S06 | I5: S07 | J5: S08 | K5: S09 | L5: S10 | M5: S11 | N5: S12 | O5: S13 | P5: S14 | Q5: S15 | R5: S16 | S5: S17 | T5: S18 | U5: S19 | V5: S20 | W5: S21 | X5: S22 | Y5: S23 | Z5: S24 | AA5: S25 | AB5: S26 | AC5: S27 | AD5: S28 | AE5: S29 | AF5: S30 | AG5: S31 | AH5: S32 | AI5: S33 | AJ5: S34 | AK5: S35 | AL5: S36 | AM5: S37 | AN5: S38 | AO5: S39 | AP5: S40 | AQ5: S41 | AR5: S42 | AS5: S43 | AT5: S44 | AU5: S45 | AV5: S46 | AW5: S47 | AX5: S48 | AY5: S49 | AZ5: S50 | BA5: S51 | BB5: S52 | BC5: S53 | BD5: S54 | BE5: S55 | BF5: S56 | BG5: S57 | BH5: S58 | BI5: S59 | BJ5: S60 | BK5: S61 | BL5: S62 | BM5: S63 | BN5: LAB | BO5: CAP | BP5: PTAX | BQ5: CTAX | BR5: DTAX | BS5: HOH | BT5: GOV | BU5: INV | BV5: EXT | BW5: TOTAL
A6: S00 | B6: 4.8162562e+08 | C6: 373000.82 | D6: 198259.79 | E6: 3987287.3 | F6: 8.7138932e+08 | G6: 63339367 | H6: 2224810 | I6: 1458635 | J6: 129394.78 | K6: 79985.731 | L6: 2809629.5 | M6: 500984.51 | N6: 11124154 | O6: 1463830.8 | P6: 54920.8 | Q6: 964984.6 | R6: 70247.452 | S6: 494710.12 | T6: 1054643.6 | U6: 115216.41 | V6: 133070.96 | W6: 826810.92 | X6: 55671.386 | Y6: 2502208.3 | Z6: 25383.815 | AA6: 45464.226 | AB6: 33543388 | AC6: 7594546.1 | AD6: 10538132 | AE6: 2259053 | AF6: 19675318 | AG6: 2970681.4 | AH6: 38981.16 | AI6: 5880456.7 | AJ6: 418351.53 | AK6: 46993862 | AL6: 63875.093 | AM6: 101279.29 | AN6: 207385.93 | AO6: 361057.41 | AP6: 23016.757 | AQ6: 1229.0819 | AR6: 4736.7269 | AS6: 1792955.4 | AT6: 193.69989 | AU6: 1520571 | AV6: 1628627 | AW6: 31415.099 | AX6: 564315.8 | AY6: 1634735.9 | AZ6: 926416.52 | BA6: 21624.501 | BB6: 1002345.7 | BC6: 843179.38 | BD6: 19294523 | BE6: 1684253.5 | BF6: 763101.36 | BG6: 1837292.2 | BH6: 2579205.7 | BI6: 641765.69 | BJ6: 1146756.8 | BK6: 171972.8 | BL6: 645153.79 | BM6: 0 | BN6: 0 | BO6: 0 | BP6: 0 | BQ6: 0 | BR6: 0 | BS6: 9.7159741e+08 | BT6: 14221.956 | BU6: 85577392 | BV6: 1.9186762e+08 | BW6: =SUM(B6:BV6) -> 2.86551e+09
A7: S01 | B7: 2086843.4 | C7: 1712813.8 | D7: 118297.43 | E7: 237.28099 | F7: 1882440.8 | G7: 1203488.5 | H7: 19936501 | I7: 20821414 | J7: 54.213876 | K7: 1178.9715 | L7: 592319.22 | M7: 22877.194 | N7: 5749.5559 | O7: 31280.692 | P7: 212.85021 | Q7: 20216.001 | R7: 72.099848 | S7: 10101.021 | T7: 8761.7621 | U7: 337.69 | V7: 1020.774 | W7: 87456.789 | X7: 175.5877 | Y7: 1624.0754 | Z7: 1.6575658 | AA7: 686.45391 | AB7: 49834.714 | AC7: 2073.9995 | AD7: 233079.57 | AE7: 3222.2754 | AF7: 2106.2249 | AG7: 203.32215 | AH7: 366.58371 | AI7: 1456.6636 | AJ7: 805.80858 | AK7: 10933.72 | AL7: 121.43652 | AM7: 182.88781 | AN7: 15.270212 | AO7: 215.99986 | AP7: 2.9075891 | AQ7: 0.42979218 | AR7: 3.2208276 | AS7: 6210.6582 | AT7: 0 | AU7: 767.8347 | AV7: 24611.481 | AW7: 37.261894 | AX7: 21398.35 | AY7: 918.0257 | AZ7: 672.55338 | BA7: 231.8191 | BB7: 243.1737 | BC7: 65835.378 | BD7: 17319.511 | BE7: 16619.528 | BF7: 7474.8495 | BG7: 61.319333 | BH7: 1468.7547 | BI7: 2486.4015 | BJ7: 3767.4223 | BK7: 44399.369 | BL7: 387.11819 | BM7: 0 | BN7: 0 | BO7: 0 | BP7: 0 | BQ7: 0 | BR7: 0 | BS7: 20301030 | BT7: 282.39558 | BU7: -291109.61 | BV7: 359811.12 | BW7: =SUM(B7:BV7) -> 69435713
A8: S02 | B8: 0 | C8: 0 | D8: 1357836.2 | E8: 1080.1816 | F8: 250901.16 | G8: 2342.8529 | H8: 96.887053 | I8: 1029.7204 | J8: 110.80607 | K8: 66.586699 | L8: 1780.6737 | M8: 107.63965 | N8: 635.34831 | O8: 1227.3457 | P8: 684.85559 | Q8: 641.94469 | R8: 76.886601 | S8: 1881.732 | T8: 625.35174 | U8: 572.10968 | V8: 182.12542 | W8: 614.27936 | X8: 297.26984 | Y8: 580.69082 | Z8: 73.586766 | AA8: 94.047473 | AB8: 10288.916 | AC8: 714.05572 | AD8: 102158.87 | AE8: 789.43701 | AF8: 3718.0201 | AG8: 1346.614 | AH8: 1345.9892 | AI8: 4251.3442 | AJ8: 220.53073 | AK8: 125641.61 | AL8: 62.952386 | AM8: 162.72509 | AN8: 57.277348 | AO8: 321.33755 | AP8: 13.005874 | AQ8: 1.9227451 | AR8: 14.406978 | AS8: 1542.6809 | AT8: 0 | AU8: 863.69983 | AV8: 650.63316 | AW8: 45.267868 | AX8: 200.52308 | AY8: 538.40274 | AZ8: 174.88622 | BA8: 93.635348 | BB8: 705.19629 | BC8: 1176.1778 | BD8: 69710.332 | BE8: 1368.9991 | BF8: 21403.171 | BG8: 349.75468 | BH8: 196.88451 | BI8: 662.30348 | BJ8: 46.632224 | BK8: 51.480513 | BL8: 427.41252 | BM8: 0 | BN8: 0 | BO8: 0 | BP8: 0 | BQ8: 0 | BR8: 0 | BS8: 12262650 | BT8: 0.62056575 | BU8: 40303435 | BV8: 14720468 | BW8: =SUM(B8:BV8) -> 69261411
A9: S03 | B9: 4368243 | C9: 198192.81 | D9: 50650.843 | E9: 58167164 | F9: 8045510.3 | G9: 6587524.5 | H9: 1807956.5 | I9: 2768079.9 | J9: 489142.72 | K9: 4.3223111e+08 | L9: 15829000 | M9: 236336.17 | N9: 4574641.4 | O9: 66633183 | P9: 1.0355186e+08 | Q9: 9441331.3 | R9: 304885.54 | S9: 3891308 | T9: 4112814.4 | U9: 3460494.1 | V9: 1225051.2 | W9: 3785508.9 | X9: 1321681.8 | Y9: 4.6174079e+08 | Z9: 762627.84 | AA9: 1136444 | AB9: 83138055 | AC9: 1847105.1 | AD9: 14809357 | AE9: 1968734.1 | AF9: 36618443 | AG9: 1475746.2 | AH9: 164346.51 | AI9: 3267264 | AJ9: 186910.44 | AK9: 3028591.1 | AL9: 32502.082 | AM9: 87563.264 | AN9: 65355.996 | AO9: 186251.35 | AP9: 40282.907 | AQ9: 1713.9674 | AR9: 56122.376 | AS9: 1585888.6 | AT9: 359066.85 | AU9: 1301489.3 | AV9: 2826342.2 | AW9: 63203.695 | AX9: 236891.93 | AY9: 243986.69 | AZ9: 561711.68 | BA9: 116421.07 | BB9: 481999.71 | BC9: 1602886.5 | BD9: 600175.2 | BE9: 272550.9 | BF9: 3426921.1 | BG9: 66015.546 | BH9: 229237.01 | BI9: 146629.66 | BJ9: 66962.705 | BK9: 62904.757 | BL9: 301875.76 | BM9: 0 | BN9: 0 | BO9: 0 | BP9: 0 | BQ9: 0 | BR9: 0 | BS9: 48854651 | BT9: 3332417.9 | BU9: 38772963 | BV9: 76817277 | BW9: =SUM(B9:BV9) -> 1.5260263e+09
A10: S04 | B10: 79995435 | C10: 46981.544 | D10: 2171060.7 | E10: 3227901.6 | F10: 4.1278663e+08 | G10: 17475567 | H10: 2345987.5 | I10: 14919368 | J10: 2604573 | K10: 2969989.5 | L10: 10915798 | M10: 2430172.4 | N10: 7764607.1 | O10: 4968842.5 | P10: 3014461 | Q10: 4043727.9 | R10: 710576.23 | S10: 2640791.3 | T10: 3587592.9 | U10: 3603835 | V10: 1175412 | W10: 3024798.7 | X10: 1531274.1 | Y10: 9528373.6 | Z10: 656439.08 | AA10: 1562970 | AB10: 47684748 | AC10: 4828602.5 | AD10: 12291422 | AE10: 9840531.1 | AF10: 13448560 | AG10: 455924.53 | AH10: 747386.86 | AI10: 5682226.9 | AJ10: 1462220.4 | AK10: 2.1351977e+08 | AL10: 827873.93 | AM10: 505786.97 | AN10: 441685.45 | AO10: 900807.64 | AP10: 1047301.1 | AQ10: 35983.228 | AR10: 279964.8 | AS10: 5394915.7 | AT10: 295716.13 | AU10: 4537863.7 | AV10: 2138865.8 | AW10: 113978.72 | AX10: 1751218.2 | AY10: 1845887.1 | AZ10: 1544260.9 | BA10: 481612.48 | BB10: 2384620.4 | BC10: 7112641.8 | BD10: 18810762 | BE10: 3731123.8 | BF10: 4402392.8 | BG10: 4288570.4 | BH10: 5348168.6 | BI10: 1980764.4 | BJ10: 2751920.9 | BK10: 260693.97 | BL10: 2006985.9 | BM10: 0 | BN10: 0 | BO10: 0 | BP10: 0 | BQ10: 0 | BR10: 0 | BS10: 1.879428e+09 | BT10: 1200962.6 | BU10: -1.6077828e+08 | BV10: 4.0931993e+08 | BW10: =SUM(B10:BV10) -> 3.1140575e+09
A11: S05 | B11: 2564962.4 | C11: 85213.379 | D11: 178097.25 | E11: 1385505.5 | F11: 6893399.9 | G11: 6.5724591e+08 | H11: 873078.79 | I11: 8540528 | J11: 3630103.9 | K11: 386169.05 | L11: 7134659.7 | M11: 1034784.1 | N11: 12604185 | O11: 4128620.7 | P11: 2100361.4 | Q11: 3917770.8 | R11: 648888.98 | S11: 3114191.1 | T11: 6708853.1 | U11: 9660952.5 | V11: 2649968.2 | W11: 19301048 | X11: 1560561 | Y11: 5503881.6 | Z11: 220877.92 | AA11: 2893707.6 | AB11: 23673872 | AC11: 3435489.4 | AD11: 23998667 | AE11: 8318448.9 | AF11: 5946789.5 | AG11: 515629.91 | AH11: 660573.29 | AI11: 2244873.5 | AJ11: 1121933.7 | AK11: 7939489.9 | AL11: 765503.92 | AM11: 447116.64 | AN11: 322135.25 | AO11: 548586.06 | AP11: 404644.87 | AQ11: 30108.528 | AR11: 171222.35 | AS11: 2581375.9 | AT11: 266382.91 | AU11: 2287771.2 | AV11: 1485303 | AW11: 59521.914 | AX11: 1911137.1 | AY11: 1083614.4 | AZ11: 664263.93 | BA11: 301960.26 | BB11: 1022066.4 | BC11: 3789002.2 | BD11: 8160364.6 | BE11: 1170052.1 | BF11: 1796100.5 | BG11: 300059.8 | BH11: 492176.68 | BI11: 928882.66 | BJ11: 274557.98 | BK11: 246121.53 | BL11: 1353939.8 | BM11: 0 | BN11: 0 | BO11: 0 | BP11: 0 | BQ11: 0 | BR11: 0 | BS11: 9.470129e+08 | BT11: 520833.68 | BU11: -25952489 | BV11: 5.9503788e+08 | BW11: =SUM(B11:BV11) -> 2.3923051e+09
A12: S06 | B12: 1441681.1 | C12: 18939.015 | D12: 31657.806 | E12: 1376587.5 | F12: 5844669 | G12: 2460937.4 | H12: 45440307 | I12: 2295748.1 | J12: 471283.08 | K12: 231512.44 | L12: 1662589.2 | M12: 131345.11 | N12: 4285019 | O12: 9803550.7 | P12: 4072672.4 | Q12: 9361423.3 | R12: 462596.77 | S12: 4317438.9 | T12: 3287500.7 | U12: 6548591 | V12: 1807802.5 | W12: 29512793 | X12: 1016397.4 | Y12: 1974993.2 | Z12: 187291.58 | AA12: 536670.15 | AB12: 63080887 | AC12: 1003846.9 | AD12: 5125950.2 | AE12: 3071223.9 | AF12: 4913395.3 | AG12: 352274.61 | AH12: 81007.554 | AI12: 732395.64 | AJ12: 171307.53 | AK12: 2288845.6 | AL12: 33619.763 | AM12: 73216.67 | AN12: 66178.438 | AO12: 158893.28 | AP12: 27093.072 | AQ12: 354.727 | AR12: 6616.3235 | AS12: 1059138.3 | AT12: 195740.87 | AU12: 803612.86 | AV12: 2270640.6 | AW12: 15042.992 | AX12: 413562.1 | AY12: 538366.86 | AZ12: 787398.62 | BA12: 31747.779 | BB12: 154217.13 | BC12: 578816.73 | BD12: 469970.4 | BE12: 129586.66 | BF12: 479100.5 | BG12: 85126.263 | BH12: 153285.23 | BI12: 118302.66 | BJ12: 34343.083 | BK12: 112092.13 | BL12: 247018.76 | BM12: 0 | BN12: 0 | BO12: 0 | BP12: 0 | BQ12: 0 | BR12: 0 | BS12: 6041347.5 | BT12: 38147.895 | BU12: 26461669 | BV12: 38279451 | BW12: =SUM(B12:BV12) -> 2.9926683e+08
A13: S07 | B13: 5368480.5 | C13: 192409.91 | D13: 239391.92 | E13: 873695.38 | F13: 24672530 | G13: 21819430 | H13: 10614534 | I13: 91916951 | J13: 17842191 | K13: 778444.37 | L13: 13060688 | M13: 2309663.9 | N13: 17685332 | O13: 6925925.5 | P13: 2471313 | Q13: 4332674.6 | R13: 1205311.8 | S13: 4848669.1 | T13: 3896730.9 | U13: 4996601.8 | V13: 914353.85 | W13: 5299483.5 | X13: 2252005.8 | Y13: 3268146.3 | Z13: 304762.48 | AA13: 3744652.8 | AB13: 8977965.6 | AC13: 1419269.1 | AD13: 11071978 | AE13: 16323624 | AF13: 2834580.3 | AG13: 178169.98 | AH13: 354915.81 | AI13: 1102892.2 | AJ13: 582462.53 | AK13: 6882640.1 | AL13: 3534178.4 | AM13: 165836.96 | AN13: 190634.12 | AO13: 605981.8 | AP13: 4399177.6 | AQ13: 74429.876 | AR13: 1556368.9 | AS13: 1134043.8 | AT13: 331087.14 | AU13: 983400.9 | AV13: 963774.86 | AW13: 115170.24 | AX13: 1716066.9 | AY13: 1004480.1 | AZ13: 244597.49 | BA13: 112553.62 | BB13: 376978.77 | BC13: 2338895.4 | BD13: 4727053.1 | BE13: 2891032.3 | BF13: 3431761.8 | BG13: 533327.1 | BH13: 968562.68 | BI13: 357905.18 | BJ13: 176429.02 | BK13: 113094.76 | BL13: 658443.47 | BM13: 0 | BN13: 0 | BO13: 0 | BP13: 0 | BQ13: 0 | BR13: 0 | BS13: 1.1134469e+08 | BT13: 29251.724 | BU13: 18811545 | BV13: 78424453 | BW13: =SUM(B13:BV13) -> 5.4387808e+08
A14: S08 | B14: 77365.536 | C14: 116658.79 | D14: 4884.7306 | E14: 159657.43 | F14: 6384823.7 | G14: 10999577 | H14: 1015000 | I14: 4389709.6 | J14: 6258773.6 | K14: 65452.31 | L14: 723545.88 | M14: 672914.08 | N14: 2254134.6 | O14: 652566.47 | P14: 411605.55 | Q14: 1064356.3 | R14: 342432.35 | S14: 1328601 | T14: 1106526.1 | U14: 1001381.8 | V14: 352649.66 | W14: 948311.69 | X14: 285008.58 | Y14: 246442.02 | Z14: 61841.252 | AA14: 219975.45 | AB14: 4154812.5 | AC14: 313243.97 | AD14: 27686776 | AE14: 2382072.6 | AF14: 612140.05 | AG14: 55916.301 | AH14: 182773.04 | AI14: 255592.57 | AJ14: 130851.7 | AK14: 1177844 | AL14: 5748010.7 | AM14: 432397.58 | AN14: 80102.381 | AO14: 557206.31 | AP14: 1909058.9 | AQ14: 103920.89 | AR14: 1439523.9 | AS14: 313926.3 | AT14: 50070.028 | AU14: 461821.83 | AV14: 348131.68 | AW14: 15282.135 | AX14: 2665407.9 | AY14: 872726.95 | AZ14: 137949.12 | BA14: 83564.274 | BB14: 179905.6 | BC14: 1025018.1 | BD14: 5777865.7 | BE14: 2406814.3 | BF14: 999674.33 | BG14: 61769.82 | BH14: 256519.34 | BI14: 201221.87 | BJ14: 134311.3 | BK14: 38947.127 | BL14: 79263.943 | BM14: 0 | BN14: 0 | BO14: 0 | BP14: 0 | BQ14: 0 | BR14: 0 | BS14: 6126489.5 | BT14: 5452.9406 | BU14: 7183072.7 | BV14: 3388742.5 | BW14: =SUM(B14:BV14) -> 1.2118039e+08
A15: S09 | B15: 35618897 | C15: 536628.9 | D15: 3695003.5 | E15: 12613793 | F15: 9488803.7 | G15: 9061391.7 | H15: 2005303.2 | I15: 2308022.2 | J15: 496113.49 | K15: 21355100 | L15: 47283541 | M15: 1249328.6 | N15: 12431491 | O15: 37453773 | P15: 12024094 | Q15: 3855092.2 | R15: 479235.32 | S15: 4925013.7 | T15: 6411239.9 | U15: 7173765.7 | V15: 938445.21 | W15: 1405027.5 | X15: 1753739.4 | Y15: 14107618 | Z15: 1456857.2 | AA15: 2916291.5 | AB15: 91539215 | AC15: 10559036 | AD15: 80442676 | AE15: 27785953 | AF15: 2.3865471e+08 | AG15: 12326269 | AH15: 93938063 | AI15: 35397347 | AJ15: 9354008.9 | AK15: 6877352.7 | AL15: 64088.399 | AM15: 116239.1 | AN15: 321948.13 | AO15: 324703.55 | AP15: 543011.29 | AQ15: 321256.2 | AR15: 902345.02 | AS15: 1642198.2 | AT15: 362947.68 | AU15: 1605601.3 | AV15: 1287166.2 | AW15: 49294.58 | AX15: 228004.54 | AY15: 149163.07 | AZ15: 1577497.2 | BA15: 288169.2 | BB15: 12418287 | BC15: 8347002.4 | BD15: 64868560 | BE15: 8834972 | BF15: 3581095.6 | BG15: 1802850.3 | BH15: 2135983 | BI15: 525315.96 | BJ15: 2290431.4 | BK15: 141233.6 | BL15: 545276.85 | BM15: 0 | BN15: 0 | BO15: 0 | BP15: 0 | BQ15: 0 | BR15: 0 | BS15: 1.4858455e+08 | BT15: 12147.854 | BU15: 76729251 | BV15: 2.8050188e+08 | BW15: =SUM(B15:BV15) -> 1.4810207e+09
A16: S10 | B16: 1.1154885e+08 | C16: 312185.85 | D16: 270706.04 | E16: 9255583.3 | F16: 44203989 | G16: 1.1609562e+08 | H16: 16143151 | I16: 24090676 | J16: 5334726.3 | K16: 22051755 | L16: 3.0240055e+08 | M16: 19089824 | N16: 1.5285426e+08 | O16: 26623068 | P16: 22805364 | Q16: 20014403 | R16: 5780986.3 | S16: 32345167 | T16: 14880579 | U16: 21707545 | V16: 3434038.1 | W16: 9279394.1 | X16: 2489014.2 | Y16: 16105116 | Z16: 1223818.7 | AA16: 7332436.6 | AB16: 42700311 | AC16: 4210661.3 | AD16: 14372769 | AE16: 17022216 | AF16: 13252885 | AG16: 1045715.5 | AH16: 978616.91 | AI16: 5575531.8 | AJ16: 1091520.9 | AK16: 8333979.1 | AL16: 310839.37 | AM16: 117723.54 | AN16: 190416.04 | AO16: 489534.71 | AP16: 476989.44 | AQ16: 11217.304 | AR16: 474017.7 | AS16: 3376019.1 | AT16: 8535411.2 | AU16: 2273227.3 | AV16: 2432118.9 | AW16: 492693.38 | AX16: 813537.12 | AY16: 690336.88 | AZ16: 883212.64 | BA16: 228298.45 | BB16: 523775 | BC16: 3161407.6 | BD16: 5958379 | BE16: 1407508.5 | BF16: 5747711.7 | BG16: 529796.7 | BH16: 270316.1 | BI16: 650893.19 | BJ16: 316347.59 | BK16: 130012.92 | BL16: 2153650.3 | BM16: 0 | BN16: 0 | BO16: 0 | BP16: 0 | BQ16: 0 | BR16: 0 | BS16: 1.4125155e+08 | BT16: 722502.66 | BU16: 43858365 | BV16: 2.9569742e+08 | BW16: =SUM(B16:BV16) -> 1.6404322e+09
A17: S11 | B17: 2271583.5 | C17: 5404.0825 | D17: 13764.228 | E17: 172000.69 | F17: 5980652.1 | G17: 1522063.1 | H17: 175333.42 | I17: 931822.63 | J17: 182318.34 | K17: 164875.81 | L17: 5408175.3 | M17: 21216932 | N17: 1410221.3 | O17: 458496.78 | P17: 318182.05 | Q17: 388191.52 | R17: 227656.71 | S17: 437864.95 | T17: 608919 | U17: 694539.98 | V17: 241045.84 | W17: 1345526.1 | X17: 320722 | Y17: 222479.41 | Z17: 84453.933 | AA17: 140060.76 | AB17: 2527107.1 | AC17: 383605.48 | AD17: 1542514.2 | AE17: 607522.47 | AF17: 2916573.6 | AG17: 171514.57 | AH17: 135382.62 | AI17: 617466.79 | AJ17: 422652.83 | AK17: 717537.88 | AL17: 42557.723 | AM17: 29628.867 | AN17: 36660.981 | AO17: 235038.46 | AP17: 105578.89 | AQ17: 3007.4748 | AR17: 21833.799 | AS17: 437924.55 | AT17: 56996.588 | AU17: 573911.71 | AV17: 563226.1 | AW17: 232911.65 | AX17: 257359.92 | AY17: 2370831 | AZ17: 152830.23 | BA17: 53609.685 | BB17: 105454.53 | BC17: 371760.13 | BD17: 452364.49 | BE17: 1277060.9 | BF17: 34109854 | BG17: 93320.081 | BH17: 129082.28 | BI17: 592475.78 | BJ17: 1836572.9 | BK17: 41290.715 | BL17: 636264.37 | BM17: 0 | BN17: 0 | BO17: 0 | BP17: 0 | BQ17: 0 | BR17: 0 | BS17: 71312495 | BT17: 1.1225265e+08 | BU17: -5231193.4 | BV17: 29230558 | BW17: =SUM(B17:BV17) -> 3.0736908e+08
... A71: CAP | B71: 1.5870137e+09 | C71: 54954349 | D71: 47704454 | E71: 2.0078301e+08 | F71: 6.17442e+08 | G71: 4.4471055e+08 | H71: 66964913 | I71: 85955983 | J71: 32115907 | K71: 1.105472e+08 | L71: 2.1112697e+08 | M71: 64721160 | N71: 1.7402455e+08 | O71: 2.3134677e+08 | P71: 2.398299e+08 | Q71: 2.700211e+08 | R71: 78529881 | S71: 1.8268936e+08 | T71: 2.0151223e+08 | U71: 2.4701239e+08 | V71: 1.3919605e+08 | W71: 1.7983024e+08 | X71: 91046124 | Y71: 4.8820901e+08 | Z71: 20305375 | AA71: 1.1341482e+08 | AB71: 9.7280582e+08 | AC71: 5.1499433e+08 | AD71: 1.038046e+09 | AE71: 1.0460079e+09 | AF71: 1.483992e+09 | AG71: 1.0673491e+08 | AH71: 1.1179606e+08 | AI71: 3.2264099e+08 | AJ71: 28120480 | AK71: 6.0017212e+08 | AL71: 19695916 | AM71: 36972819 | AN71: 77836468 | AO71: 2.942007e+08 | AP71: 3.853258e+08 | AQ71: 2.1142692e+08 | AR71: 10803380 | AS71: 6.3677545e+08 | AT71: 8.1639233e+08 | AU71: 1.6277163e+08 | AV71: 1.0256296e+08 | AW71: 3032354.2 | AX71: 34378311 | AY71: 39252070 | AZ71: 90743657 | BA71: 27430933 | BB71: 94394709 | BC71: 1.3468876e+08 | BD71: 2.5624411e+08 | BE71: 2.2469262e+08 | BF71: 1.7247525e+08 | BG71: 22162289 | BH71: 2.84555e+08 | BI71: 25176514 | BJ71: 8877119.9 | BK71: 24845239 | BL71: 55332970 | BM71: 0 | BN71: 0 | BO71: 0 | BP71: 0 | BQ71: 0 | BR71: 0 | BS71: 0 | BT71: 0 | BU71: 0 | BV71: 0 | BW71: =SUM(B71:BV71) -> 1.6659365e+10
A72: PTAX | B72: ='Tax_Bridge'!D6 -> -40497646 | C72: ='Tax_Bridge'!D7 -> 43809.329 | D72: ='Tax_Bridge'!D8 -> 43031.773 | E72: ='Tax_Bridge'!D9 -> -7361776.3 | F72: ='Tax_Bridge'!D10 -> -27938700 | G72: ='Tax_Bridge'!D11 -> -26638725 | H72: ='Tax_Bridge'!D12 -> -2261101.6 | I72: ='Tax_Bridge'!D13 -> -3752967 | J72: ='Tax_Bridge'!D14 -> -1718291.5 | K72: ='Tax_Bridge'!D15 -> -10353514 | L72: ='Tax_Bridge'!D16 -> -8568679.1 | M72: ='Tax_Bridge'!D17 -> -1753834.7 | N72: ='Tax_Bridge'!D18 -> -9273071.2 | O72: ='Tax_Bridge'!D19 -> -9311397.6 | P72: ='Tax_Bridge'!D20 -> -21409319 | Q72: ='Tax_Bridge'!D21 -> -9639454.8 | R72: ='Tax_Bridge'!D22 -> -2047540 | S72: ='Tax_Bridge'!D23 -> -9001793.8 | T72: ='Tax_Bridge'!D24 -> -7563332.3 | U72: ='Tax_Bridge'!D25 -> -13504654 | V72: ='Tax_Bridge'!D26 -> -1468215.4 | W72: ='Tax_Bridge'!D27 -> -5581316.2 | X72: ='Tax_Bridge'!D28 -> -1163064.3 | Y72: ='Tax_Bridge'!D29 -> -93626073 | Z72: ='Tax_Bridge'!D30 -> 102312.3 | AA72: ='Tax_Bridge'!D31 -> 273855 | AB72: ='Tax_Bridge'!D32 -> 9674349.8 | AC72: ='Tax_Bridge'!D33 -> 1370610.3 | AD72: ='Tax_Bridge'!D34 -> 4658252.4 | AE72: ='Tax_Bridge'!D35 -> 4950878.9 | AF72: ='Tax_Bridge'!D36 -> -92409190 | AG72: ='Tax_Bridge'!D37 -> 1484319.4 | AH72: ='Tax_Bridge'!D38 -> 722063.26 | AI72: ='Tax_Bridge'!D39 -> 93905.322 | AJ72: ='Tax_Bridge'!D40 -> 186701.5 | AK72: ='Tax_Bridge'!D41 -> 2241058.2 | AL72: ='Tax_Bridge'!D42 -> 110102.92 | AM72: ='Tax_Bridge'!D43 -> 450712.27 | AN72: ='Tax_Bridge'!D44 -> 5151657.4 | AO72: ='Tax_Bridge'!D45 -> 250202.77 | AP72: ='Tax_Bridge'!D46 -> -4588206.7 | AQ72: ='Tax_Bridge'!D47 -> 4376960.1 | AR72: ='Tax_Bridge'!D48 -> 25730948 | AS72: ='Tax_Bridge'!D49 -> 557621.11 | AT72: ='Tax_Bridge'!D50 -> 13571770 | AU72: ='Tax_Bridge'!D51 -> 870148.55 | AV72: ='Tax_Bridge'!D52 -> 6075457.8 | AW72: ='Tax_Bridge'!D53 -> 16328.141 | AX72: ='Tax_Bridge'!D54 -> 282008.61 | AY72: ='Tax_Bridge'!D55 -> 112359.72 | AZ72: ='Tax_Bridge'!D56 -> 689434.99 | BA72: ='Tax_Bridge'!D57 -> 34948.096 | BB72: ='Tax_Bridge'!D58 -> 408527.89 | BC72: ='Tax_Bridge'!D59 -> 954054.51 | BD72: ='Tax_Bridge'!D60 -> 2383913.8 | BE72: ='Tax_Bridge'!D61 -> 304712.76 | BF72: ='Tax_Bridge'!D62 -> 1248965.7 | BG72: ='Tax_Bridge'!D63 -> 28405.532 | BH72: ='Tax_Bridge'!D64 -> 49382.326 | BI72: ='Tax_Bridge'!D65 -> 117147.22 | BJ72: ='Tax_Bridge'!D66 -> 183596.26 | BK72: ='Tax_Bridge'!D67 -> 168318.55 | BL72: ='Tax_Bridge'!D68 -> 406218.74 | BM72: ='Tax_Bridge'!D69 -> 0 | BN72: 0 | BO72: 0 | BP72: 0 | BQ72: 0 | BR72: 0 | BS72: 0 | BT72: 0 | BU72: 0 | BV72: 0 | BW72: =SUM(B72:BV72) -> -3.2105281e+08
A73: CTAX | B73: ='Tax_Bridge'!C6 -> -14134007 | C73: ='Tax_Bridge'!C7 -> 144781.14 | D73: ='Tax_Bridge'!C8 -> 375484.2 | E73: ='Tax_Bridge'!C9 -> 6086615.9 | F73: ='Tax_Bridge'!C10 -> -5218209.7 | G73: ='Tax_Bridge'!C11 -> 13974022 | H73: ='Tax_Bridge'!C12 -> 1961103.9 | I73: ='Tax_Bridge'!C13 -> 4719029.3 | J73: ='Tax_Bridge'!C14 -> 1224519.9 | K73: ='Tax_Bridge'!C15 -> 59696501 | L73: ='Tax_Bridge'!C16 -> 11788426 | M73: ='Tax_Bridge'!C17 -> 1449736.7 | N73: ='Tax_Bridge'!C18 -> 8352764.3 | O73: ='Tax_Bridge'!C19 -> 9412408.5 | P73: ='Tax_Bridge'!C20 -> 19480727 | Q73: ='Tax_Bridge'!C21 -> 10251345 | R73: ='Tax_Bridge'!C22 -> 2691994.1 | S73: ='Tax_Bridge'!C23 -> 11316440 | T73: ='Tax_Bridge'!C24 -> 12801872 | U73: ='Tax_Bridge'!C25 -> 15624390 | V73: ='Tax_Bridge'!C26 -> 5620924.9 | W73: ='Tax_Bridge'!C27 -> 5442014 | X73: ='Tax_Bridge'!C28 -> 3919814.8 | Y73: ='Tax_Bridge'!C29 -> 70856532 | Z73: ='Tax_Bridge'!C30 -> 834707.38 | AA73: ='Tax_Bridge'!C31 -> 2361625.3 | AB73: ='Tax_Bridge'!C32 -> 44651318 | AC73: ='Tax_Bridge'!C33 -> 7141115.1 | AD73: ='Tax_Bridge'!C34 -> 20893376 | AE73: ='Tax_Bridge'!C35 -> 11309660 | AF73: ='Tax_Bridge'!C36 -> 28811349 | AG73: ='Tax_Bridge'!C37 -> 2184835.7 | AH73: ='Tax_Bridge'!C38 -> 9516133.4 | AI73: ='Tax_Bridge'!C39 -> 7581257.5 | AJ73: ='Tax_Bridge'!C40 -> 1982026.9 | AK73: ='Tax_Bridge'!C41 -> 28822791 | AL73: ='Tax_Bridge'!C42 -> 1024249.6 | AM73: ='Tax_Bridge'!C43 -> 14797937 | AN73: ='Tax_Bridge'!C44 -> 4641329.5 | AO73: ='Tax_Bridge'!C45 -> 3392707.8 | AP73: ='Tax_Bridge'!C46 -> 31756525 | AQ73: ='Tax_Bridge'!C47 -> 10415267 | AR73: ='Tax_Bridge'!C48 -> 2726673.4 | AS73: ='Tax_Bridge'!C49 -> 4777313 | AT73: ='Tax_Bridge'!C50 -> 3765463.1 | AU73: ='Tax_Bridge'!C51 -> 2857008.8 | AV73: ='Tax_Bridge'!C52 -> 2643946.8 | AW73: ='Tax_Bridge'!C53 -> 242203.99 | AX73: ='Tax_Bridge'!C54 -> 4304219.8 | AY73: ='Tax_Bridge'!C55 -> 497193.35 | AZ73: ='Tax_Bridge'!C56 -> 2491866.7 | BA73: ='Tax_Bridge'!C57 -> 579334.72 | BB73: ='Tax_Bridge'!C58 -> 4165581 | BC73: ='Tax_Bridge'!C59 -> 3282419.6 | BD73: ='Tax_Bridge'!C60 -> 12797128 | BE73: ='Tax_Bridge'!C61 -> 4336635.7 | BF73: ='Tax_Bridge'!C62 -> 5822874.6 | BG73: ='Tax_Bridge'!C63 -> 406046.53 | BH73: ='Tax_Bridge'!C64 -> 2332978 | BI73: ='Tax_Bridge'!C65 -> 1146264.4 | BJ73: ='Tax_Bridge'!C66 -> 1369246 | BK73: ='Tax_Bridge'!C67 -> 685216.46 | BL73: ='Tax_Bridge'!C68 -> 710302.21 | BM73: ='Tax_Bridge'!C69 -> 0 | BN73: 0 | BO73: 0 | BP73: 0 | BQ73: 0 | BR73: 0 | BS73: ='Tax_Bridge'!C70 -> 1.3963945e+09 | BT73: ='Tax_Bridge'!C71 -> 97123097 | BU73: ='Tax_Bridge'!C72 -> 9.5222668e+08 | BV73: ='Tax_Bridge'!C73 -> 0 | BW73: =SUM(B73:BV73) -> 2.9976417e+09
A74: DTAX | B74: 0 | C74: 0 | D74: 0 | E74: 0 | F74: 0 | G74: 0 | H74: 0 | I74: 0 | J74: 0 | K74: 0 | L74: 0 | M74: 0 | N74: 0 | O74: 0 | P74: 0 | Q74: 0 | R74: 0 | S74: 0 | T74: 0 | U74: 0 | V74: 0 | W74: 0 | X74: 0 | Y74: 0 | Z74: 0 | AA74: 0 | AB74: 0 | AC74: 0 | AD74: 0 | AE74: 0 | AF74: 0 | AG74: 0 | AH74: 0 | AI74: 0 | AJ74: 0 | AK74: 0 | AL74: 0 | AM74: 0 | AN74: 0 | AO74: 0 | AP74: 0 | AQ74: 0 | AR74: 0 | AS74: 0 | AT74: 0 | AU74: 0 | AV74: 0 | AW74: 0 | AX74: 0 | AY74: 0 | AZ74: 0 | BA74: 0 | BB74: 0 | BC74: 0 | BD74: 0 | BE74: 0 | BF74: 0 | BG74: 0 | BH74: 0 | BI74: 0 | BJ74: 0 | BK74: 0 | BL74: 0 | BM74: 0 | BN74: 0 | BO74: 0 | BP74: 0 | BQ74: 0 | BR74: 0 | BS74: ='Tax_Bridge'!B78 -> 1.7620531e+09 | BT74: 0 | BU74: 0 | BV74: 0 | BW74: =SUM(B74:BV74) -> 1.7620531e+09
A75: HOH | B75: 0 | C75: 0 | D75: 0 | E75: 0 | F75: 0 | G75: 0 | H75: 0 | I75: 0 | J75: 0 | K75: 0 | L75: 0 | M75: 0 | N75: 0 | O75: 0 | P75: 0 | Q75: 0 | R75: 0 | S75: 0 | T75: 0 | U75: 0 | V75: 0 | W75: 0 | X75: 0 | Y75: 0 | Z75: 0 | AA75: 0 | AB75: 0 | AC75: 0 | AD75: 0 | AE75: 0 | AF75: 0 | AG75: 0 | AH75: 0 | AI75: 0 | AJ75: 0 | AK75: 0 | AL75: 0 | AM75: 0 | AN75: 0 | AO75: 0 | AP75: 0 | AQ75: 0 | AR75: 0 | AS75: 0 | AT75: 0 | AU75: 0 | AV75: 0 | AW75: 0 | AX75: 0 | AY75: 0 | AZ75: 0 | BA75: 0 | BB75: 0 | BC75: 0 | BD75: 0 | BE75: 0 | BF75: 0 | BG75: 0 | BH75: 0 | BI75: 0 | BJ75: 0 | BK75: 0 | BL75: 0 | BM75: 0 | BN75: =SUM(B70:BM70) -> 7.7555154e+09 | BO75: =SUM(B71:BM71) -> 1.6659365e+10 | BP75: 0 | BQ75: 0 | BR75: 0 | BS75: 0 | BT75: 0 | BU75: 0 | BV75: 0 | BW75: =SUM(B75:BV75) -> 2.441488e+10
A76: GOV | B76: 0 | C76: 0 | D76: 0 | E76: 0 | F76: 0 | G76: 0 | H76: 0 | I76: 0 | J76: 0 | K76: 0 | L76: 0 | M76: 0 | N76: 0 | O76: 0 | P76: 0 | Q76: 0 | R76: 0 | S76: 0 | T76: 0 | U76: 0 | V76: 0 | W76: 0 | X76: 0 | Y76: 0 | Z76: 0 | AA76: 0 | AB76: 0 | AC76: 0 | AD76: 0 | AE76: 0 | AF76: 0 | AG76: 0 | AH76: 0 | AI76: 0 | AJ76: 0 | AK76: 0 | AL76: 0 | AM76: 0 | AN76: 0 | AO76: 0 | AP76: 0 | AQ76: 0 | AR76: 0 | AS76: 0 | AT76: 0 | AU76: 0 | AV76: 0 | AW76: 0 | AX76: 0 | AY76: 0 | AZ76: 0 | BA76: 0 | BB76: 0 | BC76: 0 | BD76: 0 | BE76: 0 | BF76: 0 | BG76: 0 | BH76: 0 | BI76: 0 | BJ76: 0 | BK76: 0 | BL76: 0 | BM76: 0 | BN76: 0 | BO76: 0 | BP76: =SUM(B72:BV72) -> -3.2105281e+08 | BQ76: =SUM(B73:BV73) -> 2.9976417e+09 | BR76: =BS74 -> 1.7620531e+09 | BS76: 0 | BT76: 0 | BU76: 0 | BV76: 0 | BW76: =SUM(B76:BV76) -> 4.438642e+09
A77: INV | B77: 0 | C77: 0 | D77: 0 | E77: 0 | F77: 0 | G77: 0 | H77: 0 | I77: 0 | J77: 0 | K77: 0 | L77: 0 | M77: 0 | N77: 0 | O77: 0 | P77: 0 | Q77: 0 | R77: 0 | S77: 0 | T77: 0 | U77: 0 | V77: 0 | W77: 0 | X77: 0 | Y77: 0 | Z77: 0 | AA77: 0 | AB77: 0 | AC77: 0 | AD77: 0 | AE77: 0 | AF77: 0 | AG77: 0 | AH77: 0 | AI77: 0 | AJ77: 0 | AK77: 0 | AL77: 0 | AM77: 0 | AN77: 0 | AO77: 0 | AP77: 0 | AQ77: 0 | AR77: 0 | AS77: 0 | AT77: 0 | AU77: 0 | AV77: 0 | AW77: 0 | AX77: 0 | AY77: 0 | AZ77: 0 | BA77: 0 | BB77: 0 | BC77: 0 | BD77: 0 | BE77: 0 | BF77: 0 | BG77: 0 | BH77: 0 | BI77: 0 | BJ77: 0 | BK77: 0 | BL77: 0 | BM77: 0 | BN77: 0 | BO77: 0 | BP77: 0 | BQ77: 0 | BR77: 0 | BS77: =BN75+BO75-SUM(BS6:BS69)-BS73-BS74 -> 6.6137252e+09 | BT77: =BP76+BQ76+BR76-SUM(BT6:BT69)-BT73 -> 8.5279886e+08 | BU77: 0 | BV77: =SUM(B78:BM78)-SUM(BV6:BV69)-BV73 -> 1.9039481e+09 | BW77: =SUM(B77:BV77) -> 9.3704722e+09
A78: EXT | B78: 3.1798032e+08 | C78: 1097532.5 | D78: 1623336.6 | E78: 9.7836884e+08 | F78: 3.1198586e+08 | G78: 2.5508781e+08 | H78: 27631731 | I78: 1.1743189e+08 | J78: 3455424.9 | K78: 6.8832424e+08 | L78: 7.7360107e+08 | M78: 1.22717e+08 | N78: 1.7646909e+08 | O78: 1.3859016e+08 | P78: 1.3834251e+09 | Q78: 2.1193057e+08 | R78: 4.2388134e+08 | S78: 3.9127213e+08 | T78: 6.2925742e+08 | U78: 8.7283506e+08 | V78: 1.7334738e+08 | W78: 1.0593555e+08 | X78: 34879672 | Y78: 31945566 | Z78: 71929.336 | AA78: 2.1593513e+08 | AB78: 67332354 | AC78: 6049565.1 | AD78: 69458753 | AE78: 12074156 | AF78: 31434098 | AG78: 5551516.4 | AH78: 17242824 | AI78: 81182169 | AJ78: 815995.03 | AK78: 38463369 | AL78: 47972970 | AM78: 14059094 | AN78: 6723111 | AO78: 59226681 | AP78: 44415950 | AQ78: 57161182 | AR78: 2040991.3 | AS78: 5515484.7 | AT78: 0 | AU78: 46863283 | AV78: 30892885 | AW78: 1684734.4 | AX78: 25400512 | AY78: 15797047 | AZ78: 61598514 | BA78: 4220295.2 | BB78: 10482706 | BC78: 7393168.9 | BD78: 36706609 | BE78: 2565200.5 | BF78: 854218.61 | BG78: 120647.87 | BH78: 1273172.8 | BI78: 990670.22 | BJ78: 3733.0035 | BK78: 358914.19 | BL78: 368709.9 | BM78: 0 | BN78: 0 | BO78: 0 | BP78: 0 | BQ78: 0 | BR78: 0 | BS78: 0 | BT78: 0 | BU78: 0 | BV78: 0 | BW78: =SUM(B78:BV78) -> 9.2033764e+09
A79: TOTAL | B79: =SUM(B6:B78) -> 2.86551e+09 | C79: =SUM(C6:C78) -> 69435713 | D79: =SUM(D6:D78) -> 69261411 | E79: =SUM(E6:E78) -> 1.5260263e+09 | F79: =SUM(F6:F78) -> 3.1140575e+09 | G79: =SUM(G6:G78) -> 2.3923051e+09 | H79: =SUM(H6:H78) -> 2.9926683e+08 | I79: =SUM(I6:I78) -> 5.4387808e+08 | ... BW79: =SUM(BW6:BW78) -> 1.3783749e+11

Sheet Macro_SAM
A2: Macro SAM view
A3: Thousand TRY; SECTORS aggregates 64 sectors for this display only.
A5: Account | B5: SECTORS | C5: LAB | D5: CAP | E5: PTAX | F5: CTAX | G5: DTAX | H5: HOH | I5: GOV | J5: INV | K5: EXT | L5: TOTAL
A6: SECTORS | B6: =SUM('SAM_73'!B6:BM69) -> 2.7707497e+10 | C6: =SUM('SAM_73'!BN6:BN69) -> 0 | D6: =SUM('SAM_73'!BO6:BO69) -> 0 | E6: =SUM('SAM_73'!BP6:BP69) -> 0 | F6: =SUM('SAM_73'!BQ6:BQ69) -> 0 | G6: =SUM('SAM_73'!BR6:BR69) -> 0 | H6: =SUM('SAM_73'!BS6:BS69) -> 1.4642707e+10 | I6: =SUM('SAM_73'!BT6:BT69) -> 3.48872e+09 | J6: =SUM('SAM_73'!BU6:BU69) -> 8.4182456e+09 | K6: =SUM('SAM_73'!BV6:BV69) -> 7.2994283e+09 | L6: =SUM(B6:K6) -> 6.1556598e+10
A7: LAB | B7: =SUM('SAM_73'!B70:BM70) -> 7.7555154e+09 | C7: =SUM('SAM_73'!BN70:BN70) -> 0 | D7: =SUM('SAM_73'!BO70:BO70) -> 0 | E7: =SUM('SAM_73'!BP70:BP70) -> 0 | F7: =SUM('SAM_73'!BQ70:BQ70) -> 0 | G7: =SUM('SAM_73'!BR70:BR70) -> 0 | H7: =SUM('SAM_73'!BS70:BS70) -> 0 | I7: =SUM('SAM_73'!BT70:BT70) -> 0 | J7: =SUM('SAM_73'!BU70:BU70) -> 0 | K7: =SUM('SAM_73'!BV70:BV70) -> 0 | L7: =SUM(B7:K7) -> 7.7555154e+09
A8: CAP | B8: =SUM('SAM_73'!B71:BM71) -> 1.6659365e+10 | C8: =SUM('SAM_73'!BN71:BN71) -> 0 | D8: =SUM('SAM_73'!BO71:BO71) -> 0 | E8: =SUM('SAM_73'!BP71:BP71) -> 0 | F8: =SUM('SAM_73'!BQ71:BQ71) -> 0 | G8: =SUM('SAM_73'!BR71:BR71) -> 0 | H8: =SUM('SAM_73'!BS71:BS71) -> 0 | I8: =SUM('SAM_73'!BT71:BT71) -> 0 | J8: =SUM('SAM_73'!BU71:BU71) -> 0 | K8: =SUM('SAM_73'!BV71:BV71) -> 0 | L8: =SUM(B8:K8) -> 1.6659365e+10
A9: PTAX | B9: =SUM('SAM_73'!B72:BM72) -> -3.2105281e+08 | C9: =SUM('SAM_73'!BN72:BN72) -> 0 | D9: =SUM('SAM_73'!BO72:BO72) -> 0 | E9: =SUM('SAM_73'!BP72:BP72) -> 0 | F9: =SUM('SAM_73'!BQ72:BQ72) -> 0 | G9: =SUM('SAM_73'!BR72:BR72) -> 0 | H9: =SUM('SAM_73'!BS72:BS72) -> 0 | I9: =SUM('SAM_73'!BT72:BT72) -> 0 | J9: =SUM('SAM_73'!BU72:BU72) -> 0 | K9: =SUM('SAM_73'!BV72:BV72) -> 0 | L9: =SUM(B9:K9) -> -3.2105281e+08
A10: CTAX | B10: =SUM('SAM_73'!B73:BM73) -> 5.5189736e+08 | C10: =SUM('SAM_73'!BN73:BN73) -> 0 | D10: =SUM('SAM_73'!BO73:BO73) -> 0 | E10: =SUM('SAM_73'!BP73:BP73) -> 0 | F10: =SUM('SAM_73'!BQ73:BQ73) -> 0 | G10: =SUM('SAM_73'!BR73:BR73) -> 0 | H10: =SUM('SAM_73'!BS73:BS73) -> 1.3963945e+09 | I10: =SUM('SAM_73'!BT73:BT73) -> 97123097 | J10: =SUM('SAM_73'!BU73:BU73) -> 9.5222668e+08 | K10: =SUM('SAM_73'!BV73:BV73) -> 0 | L10: =SUM(B10:K10) -> 2.9976417e+09
A11: DTAX | B11: =SUM('SAM_73'!B74:BM74) -> 0 | C11: =SUM('SAM_73'!BN74:BN74) -> 0 | D11: =SUM('SAM_73'!BO74:BO74) -> 0 | E11: =SUM('SAM_73'!BP74:BP74) -> 0 | F11: =SUM('SAM_73'!BQ74:BQ74) -> 0 | G11: =SUM('SAM_73'!BR74:BR74) -> 0 | H11: =SUM('SAM_73'!BS74:BS74) -> 1.7620531e+09 | I11: =SUM('SAM_73'!BT74:BT74) -> 0 | J11: =SUM('SAM_73'!BU74:BU74) -> 0 | K11: =SUM('SAM_73'!BV74:BV74) -> 0 | L11: =SUM(B11:K11) -> 1.7620531e+09
A12: HOH | B12: =SUM('SAM_73'!B75:BM75) -> 0 | C12: =SUM('SAM_73'!BN75:BN75) -> 7.7555154e+09 | D12: =SUM('SAM_73'!BO75:BO75) -> 1.6659365e+10 | E12: =SUM('SAM_73'!BP75:BP75) -> 0 | F12: =SUM('SAM_73'!BQ75:BQ75) -> 0 | G12: =SUM('SAM_73'!BR75:BR75) -> 0 | H12: =SUM('SAM_73'!BS75:BS75) -> 0 | I12: =SUM('SAM_73'!BT75:BT75) -> 0 | J12: =SUM('SAM_73'!BU75:BU75) -> 0 | K12: =SUM('SAM_73'!BV75:BV75) -> 0 | L12: =SUM(B12:K12) -> 2.441488e+10
A13: GOV | B13: =SUM('SAM_73'!B76:BM76) -> 0 | C13: =SUM('SAM_73'!BN76:BN76) -> 0 | D13: =SUM('SAM_73'!BO76:BO76) -> 0 | E13: =SUM('SAM_73'!BP76:BP76) -> -3.2105281e+08 | F13: =SUM('SAM_73'!BQ76:BQ76) -> 2.9976417e+09 | G13: =SUM('SAM_73'!BR76:BR76) -> 1.7620531e+09 | H13: =SUM('SAM_73'!BS76:BS76) -> 0 | I13: =SUM('SAM_73'!BT76:BT76) -> 0 | J13: =SUM('SAM_73'!BU76:BU76) -> 0 | K13: =SUM('SAM_73'!BV76:BV76) -> 0 | L13: =SUM(B13:K13) -> 4.438642e+09
A14: INV | B14: =SUM('SAM_73'!B77:BM77) -> 0 | C14: =SUM('SAM_73'!BN77:BN77) -> 0 | D14: =SUM('SAM_73'!BO77:BO77) -> 0 | E14: =SUM('SAM_73'!BP77:BP77) -> 0 | F14: =SUM('SAM_73'!BQ77:BQ77) -> 0 | G14: =SUM('SAM_73'!BR77:BR77) -> 0 | H14: =SUM('SAM_73'!BS77:BS77) -> 6.6137252e+09 | I14: =SUM('SAM_73'!BT77:BT77) -> 8.5279886e+08 | J14: =SUM('SAM_73'!BU77:BU77) -> 0 | K14: =SUM('SAM_73'!BV77:BV77) -> 1.9039481e+09 | L14: =SUM(B14:K14) -> 9.3704722e+09
A15: EXT | B15: =SUM('SAM_73'!B78:BM78) -> 9.2033764e+09 | C15: =SUM('SAM_73'!BN78:BN78) -> 0 | D15: =SUM('SAM_73'!BO78:BO78) -> 0 | E15: =SUM('SAM_73'!BP78:BP78) -> 0 | F15: =SUM('SAM_73'!BQ78:BQ78) -> 0 | G15: =SUM('SAM_73'!BR78:BR78) -> 0 | H15: =SUM('SAM_73'!BS78:BS78) -> 0 | I15: =SUM('SAM_73'!BT78:BT78) -> 0 | J15: =SUM('SAM_73'!BU78:BU78) -> 0 | K15: =SUM('SAM_73'!BV78:BV78) -> 0 | L15: =SUM(B15:K15) -> 9.2033764e+09
A16: TOTAL | B16: =SUM(B6:B15) -> 6.1556598e+10 | C16: =SUM(C6:C15) -> 7.7555154e+09 | D16: =SUM(D6:D15) -> 1.6659365e+10 | E16: =SUM(E6:E15) -> -3.2105281e+08 | F16: =SUM(F6:F15) -> 2.9976417e+09 | G16: =SUM(G6:G15) -> 1.7620531e+09 | H16: =SUM(H6:H15) -> 2.441488e+10 | I16: =SUM(I6:I15) -> 4.438642e+09 | ... K16: =SUM(K6:K15) -> 9.2033764e+09 | L16: =SUM(B16:K16) -> 1.3783749e+11

Sheet Accounts
A2: Account dictionary
A3: S00–S63 correspond to source sector codes 0–63. Other identifiers name institutional accounts.
A5: Account | B5: Previous code | C5: NACE | D5: Name | E5: Group | F5: Scope
A6: S00 | B6: 0 | C6: A01 | D6: Crop and animal production, hunting and related services | E6: Sector | F6: IO Total_Supply: rows/columns 0–63
A7: S01 | B7: 1 | C7: A02 | D7: Forestry and logging | E7: Sector | F7: IO Total_Supply: rows/columns 0–63
A8: S02 | B8: 2 | C8: A03 | D8: Fishing and aquaculture | E8: Sector | F8: IO Total_Supply: rows/columns 0–63
A9: S03 | B9: 3 | C9: B | D9: Mining and quarrying products/services | E9: Sector | F9: IO Total_Supply: rows/columns 0–63
A10: S04 | B10: 4 | C10: C10-C12 | D10: Food products, beverages and tobacco | E10: Sector | F10: IO Total_Supply: rows/columns 0–63
A11: S05 | B11: 5 | C11: C13-C15 | D11: Textiles, wearing apparel and leather products | E11: Sector | F11: IO Total_Supply: rows/columns 0–63
A12: S06 | B12: 6 | C12: C16 | D12: Wood and products of wood and cork | E12: Sector | F12: IO Total_Supply: rows/columns 0–63
A13: S07 | B13: 7 | C13: C17 | D13: Paper and paper products | E13: Sector | F13: IO Total_Supply: rows/columns 0–63
A14: S08 | B14: 8 | C14: C18 | D14: Printing and reproduction of recorded media | E14: Sector | F14: IO Total_Supply: rows/columns 0–63
A15: S09 | B15: 9 | C15: C19 | D15: Coke and refined petroleum products | E15: Sector | F15: IO Total_Supply: rows/columns 0–63
A16: S10 | B16: 10 | C16: C20 | D16: Chemicals and chemical products | E16: Sector | F16: IO Total_Supply: rows/columns 0–63
A17: S11 | B17: 11 | C17: C21 | D17: Basic pharmaceutical products and preparations | E17: Sector | F17: IO Total_Supply: rows/columns 0–63
... A69: S63 | B69: 63 | C69: T | D69: Activities of households as employers and for own use | E69: Sector | F69: IO Total_Supply: rows/columns 0–63
A70: LAB | D70: Labour | E70: Factor | F70: Compensation of employees
A71: CAP | D71: Capital | E71: Factor | F71: Gross operating surplus / mixed income, including depreciation
A72: PTAX | D72: Other net production taxes | E72: Tax | F72: Production taxes less subsidies; D29-D39
A73: CTAX | D73: Net product taxes | E73: Tax | F73: Commodity taxes less subsidies; D21-D31; import duties are not separately identified
A74: DTAX | D74: Direct tax | E74: Tax | F74: TurkStat D.5 general government resources; HOH → DTAX → GOV
A75: HOH | D75: Representative household | E75: Institution | F75: All labour and capital income; representative private-sector scope
A76: GOV | D76: Government | E76: Institution | F76: Tax revenue, government consumption and residual government saving
A77: INV | D77: Investment-tasarruf | E77: Institution | F77: Investment and inventories; private, government and foreign saving
A78: EXT | D78: Rest of the world | E78: Institution | F78: IO imports/exports; excludes foreign factor income and transfers

Sheet Tax_Bridge
A2: Transfer of tax data to separate SAM accounts
A3: Thousand TRY. CTAX: net product taxes. PTAX: other net production taxes. Import duties are not separate.
A5: Account | B5: Name | C5: CTAX: net product taxes | D5: PTAX: other net production taxes | E5: PTAX + CTAX | F5: Source
A6: S00 | B6: Crop and animal production, hunting and related services | C6: -14134007 | D6: -40497646 | E6: =C6+D6 -> -54631653 | F6: I_industry_io_tables_2023.xlsx / Total_Supply
A7: S01 | B7: Forestry and logging | C7: 144781.14 | D7: 43809.329 | E7: =C7+D7 -> 188590.47 | F7: I_industry_io_tables_2023.xlsx / Total_Supply
A8: S02 | B8: Fishing and aquaculture | C8: 375484.2 | D8: 43031.773 | E8: =C8+D8 -> 418515.98 | F8: I_industry_io_tables_2023.xlsx / Total_Supply
A9: S03 | B9: Mining and quarrying products/services | C9: 6086615.9 | D9: -7361776.3 | E9: =C9+D9 -> -1275160.4 | F9: I_industry_io_tables_2023.xlsx / Total_Supply
A10: S04 | B10: Food products, beverages and tobacco | C10: -5218209.7 | D10: -27938700 | E10: =C10+D10 -> -33156910 | F10: I_industry_io_tables_2023.xlsx / Total_Supply
A11: S05 | B11: Textiles, wearing apparel and leather products | C11: 13974022 | D11: -26638725 | E11: =C11+D11 -> -12664702 | F11: I_industry_io_tables_2023.xlsx / Total_Supply
A12: S06 | B12: Wood and products of wood and cork | C12: 1961103.9 | D12: -2261101.6 | E12: =C12+D12 -> -299997.72 | F12: I_industry_io_tables_2023.xlsx / Total_Supply
A13: S07 | B13: Paper and paper products | C13: 4719029.3 | D13: -3752967 | E13: =C13+D13 -> 966062.38 | F13: I_industry_io_tables_2023.xlsx / Total_Supply
A14: S08 | B14: Printing and reproduction of recorded media | C14: 1224519.9 | D14: -1718291.5 | E14: =C14+D14 -> -493771.63 | F14: I_industry_io_tables_2023.xlsx / Total_Supply
A15: S09 | B15: Coke and refined petroleum products | C15: 59696501 | D15: -10353514 | E15: =C15+D15 -> 49342988 | F15: I_industry_io_tables_2023.xlsx / Total_Supply
A16: S10 | B16: Chemicals and chemical products | C16: 11788426 | D16: -8568679.1 | E16: =C16+D16 -> 3219746.7 | F16: I_industry_io_tables_2023.xlsx / Total_Supply
A17: S11 | B17: Basic pharmaceutical products and preparations | C17: 1449736.7 | D17: -1753834.7 | E17: =C17+D17 -> -304098.04 | F17: I_industry_io_tables_2023.xlsx / Total_Supply
... A73: EXT | B73: Exports | C73: 0 | D73: 0 | E73: =C73+D73 -> 0 | F73: I_industry_io_tables_2023.xlsx / Total_Supply
A77: Transaction | B77: Value | C77: Unit | D77: Institutional side | E77: Source cell | F77: Source workbook / sheet
A78: D.5 | B78: 1.7620531e+09 | C78: thousand TRY | D78: General government resources | E78: L48 | F78: TurkStat 2023 institutional accounts / t_2023
A79: D.5 HOH | B79: 8.113405e+08 | C79: thousand TRY | D79: Household uses; excluded from the model input | E79: D48 | F79: TurkStat 2023 institutional accounts / t_2023
A80: D.51 | B80: 1.6558458e+09 | C80: thousand TRY | D80: General government resources | E80: L49 | F80: TurkStat 2023 institutional accounts / t_2023
A81: D.59 | B81: 1.0620734e+08 | C81: thousand TRY | D81: General government resources | E81: L50 | F81: TurkStat 2023 institutional accounts / t_2023
A84: TurkStat statistical release | B84: https://veriportali.tuik.gov.tr/tr/press/57929
A85: Release / reference period | B85: 9 October 2025 / 2023
A86: Method | B86: Hosoe et al. (2010), Chapter 4, pp. 47–56; Japan Tables 4.4–4.5.C

Sheet Checks
A2: Account balance checks
A3: Thousand TRY; absolute tolerance 0.001 thousand TRY = 1 TRY. Source flows preserved.
A5: Account | B5: Row total | C5: Column total | D5: Difference | E5: Absolute difference | F5: Relative difference | G5: Result
A6: S00 | B6: ='SAM_73'!BW6 -> 2.86551e+09 | C6: ='SAM_73'!B79 -> 2.86551e+09 | D6: =B6-C6 -> -3.8146973e-06 | E6: =ABS(D6) -> 3.8146973e-06 | F6: =E6/MAX(ABS(B6),ABS(C6),1) -> 1.3312455e-15 | G6: =IF(E6<=0.001,"Pass","Difference detected") -> Pass
A7: S01 | B7: ='SAM_73'!BW7 -> 69435713 | C7: ='SAM_73'!C79 -> 69435713 | D7: =B7-C7 -> -7.4505806e-08 | E7: =ABS(D7) -> 7.4505806e-08 | F7: =E7/MAX(ABS(B7),ABS(C7),1) -> 1.0730185e-15 | G7: =IF(E7<=0.001,"Pass","Difference detected") -> Pass
A8: S02 | B8: ='SAM_73'!BW8 -> 69261411 | C8: ='SAM_73'!D79 -> 69261411 | D8: =B8-C8 -> 2.9802322e-08 | E8: =ABS(D8) -> 2.9802322e-08 | F8: =E8/MAX(ABS(B8),ABS(C8),1) -> 4.3028754e-16 | G8: =IF(E8<=0.001,"Pass","Difference detected") -> Pass
A9: S03 | B9: ='SAM_73'!BW9 -> 1.5260263e+09 | C9: ='SAM_73'!E79 -> 1.5260263e+09 | D9: =B9-C9 -> -1.1920929e-06 | E9: =ABS(D9) -> 1.1920929e-06 | F9: =E9/MAX(ABS(B9),ABS(C9),1) -> 7.8117452e-16 | G9: =IF(E9<=0.001,"Pass","Difference detected") -> Pass
A10: S04 | B10: ='SAM_73'!BW10 -> 3.1140575e+09 | C10: ='SAM_73'!F79 -> 3.1140575e+09 | D10: =B10-C10 -> -4.7683716e-06 | E10: =ABS(D10) -> 4.7683716e-06 | F10: =E10/MAX(ABS(B10),ABS(C10),1) -> 1.5312407e-15 | G10: =IF(E10<=0.001,"Pass","Difference detected") -> Pass
A11: S05 | B11: ='SAM_73'!BW11 -> 2.3923051e+09 | C11: ='SAM_73'!G79 -> 2.3923051e+09 | D11: =B11-C11 -> -2.3841858e-06 | E11: =ABS(D11) -> 2.3841858e-06 | F11: =E11/MAX(ABS(B11),ABS(C11),1) -> 9.9660605e-16 | G11: =IF(E11<=0.001,"Pass","Difference detected") -> Pass
A12: S06 | B12: ='SAM_73'!BW12 -> 2.9926683e+08 | C12: ='SAM_73'!H79 -> 2.9926683e+08 | D12: =B12-C12 -> -5.364418e-07 | E12: =ABS(D12) -> 5.364418e-07 | F12: =E12/MAX(ABS(B12),ABS(C12),1) -> 1.7925201e-15 | G12: =IF(E12<=0.001,"Pass","Difference detected") -> Pass
A13: S07 | B13: ='SAM_73'!BW13 -> 5.4387808e+08 | C13: ='SAM_73'!I79 -> 5.4387808e+08 | D13: =B13-C13 -> -8.3446503e-07 | E13: =ABS(D13) -> 8.3446503e-07 | F13: =E13/MAX(ABS(B13),ABS(C13),1) -> 1.5342869e-15 | G13: =IF(E13<=0.001,"Pass","Difference detected") -> Pass
A14: S08 | B14: ='SAM_73'!BW14 -> 1.2118039e+08 | C14: ='SAM_73'!J79 -> 1.2118039e+08 | D14: =B14-C14 -> -2.2351742e-07 | E14: =ABS(D14) -> 2.2351742e-07 | F14: =E14/MAX(ABS(B14),ABS(C14),1) -> 1.8445016e-15 | G14: =IF(E14<=0.001,"Pass","Difference detected") -> Pass
A15: S09 | B15: ='SAM_73'!BW15 -> 1.4810207e+09 | C15: ='SAM_73'!K79 -> 1.4810207e+09 | D15: =B15-C15 -> -2.8610229e-06 | E15: =ABS(D15) -> 2.8610229e-06 | F15: =E15/MAX(ABS(B15),ABS(C15),1) -> 1.9317913e-15 | G15: =IF(E15<=0.001,"Pass","Difference detected") -> Pass
A16: S10 | B16: ='SAM_73'!BW16 -> 1.6404322e+09 | C16: ='SAM_73'!L79 -> 1.6404322e+09 | D16: =B16-C16 -> -1.4305115e-06 | E16: =ABS(D16) -> 1.4305115e-06 | F16: =E16/MAX(ABS(B16),ABS(C16),1) -> 8.7203326e-16 | G16: =IF(E16<=0.001,"Pass","Difference detected") -> Pass
A17: S11 | B17: ='SAM_73'!BW17 -> 3.0736908e+08 | C17: ='SAM_73'!M79 -> 3.0736908e+08 | D17: =B17-C17 -> -5.9604645e-08 | E17: =ABS(D17) -> 5.9604645e-08 | F17: =E17/MAX(ABS(B17),ABS(C17),1) -> 1.9391881e-16 | G17: =IF(E17<=0.001,"Pass","Difference detected") -> Pass
A18: S12 | B18: ='SAM_73'!BW18 -> 1.0201353e+09 | C18: ='SAM_73'!N79 -> 1.0201353e+09 | D18: =B18-C18 -> -1.3113022e-06 | E18: =ABS(D18) -> 1.3113022e-06 | F18: =E18/MAX(ABS(B18),ABS(C18),1) -> 1.2854199e-15 | G18: =IF(E18<=0.001,"Pass","Difference detected") -> Pass
A19: S13 | B19: ='SAM_73'!BW19 -> 1.0625887e+09 | C19: ='SAM_73'!O79 -> 1.0625887e+09 | D19: =B19-C19 -> -1.9073486e-06 | E19: =ABS(D19) -> 1.9073486e-06 | F19: =E19/MAX(ABS(B19),ABS(C19),1) -> 1.7950019e-15 | G19: =IF(E19<=0.001,"Pass","Difference detected") -> Pass
A20: S14 | B20: ='SAM_73'!BW20 -> 3.1310016e+09 | C20: ='SAM_73'!P79 -> 3.1310016e+09 | D20: =B20-C20 -> -3.3378601e-06 | E20: =ABS(D20) -> 3.3378601e-06 | F20: =E20/MAX(ABS(B20),ABS(C20),1) -> 1.0660678e-15 | G20: =IF(E20<=0.001,"Pass","Difference detected") -> Pass
A21: S15 | B21: ='SAM_73'!BW21 -> 1.4000235e+09 | C21: ='SAM_73'!Q79 -> 1.4000235e+09 | D21: =B21-C21 -> -4.7683716e-07 | E21: =ABS(D21) -> 4.7683716e-07 | F21: =E21/MAX(ABS(B21),ABS(C21),1) -> 3.4059226e-16 | G21: =IF(E21<=0.001,"Pass","Difference detected") -> Pass
A22: S16 | B22: ='SAM_73'!BW22 -> 7.2223706e+08 | C22: ='SAM_73'!R79 -> 7.2223706e+08 | D22: =B22-C22 -> -8.3446503e-07 | E22: =ABS(D22) -> 8.3446503e-07 | F22: =E22/MAX(ABS(B22),ABS(C22),1) -> 1.1553894e-15 | G22: =IF(E22<=0.001,"Pass","Difference detected") -> Pass
A23: S17 | B23: ='SAM_73'!BW23 -> 1.3120674e+09 | C23: ='SAM_73'!S79 -> 1.3120674e+09 | D23: =B23-C23 -> -1.1920929e-06 | E23: =ABS(D23) -> 1.1920929e-06 | F23: =E23/MAX(ABS(B23),ABS(C23),1) -> 9.0856071e-16 | G23: =IF(E23<=0.001,"Pass","Difference detected") -> Pass
A24: S18 | B24: ='SAM_73'!BW24 -> 1.5457976e+09 | C24: ='SAM_73'!T79 -> 1.5457976e+09 | D24: =B24-C24 -> -1.6689301e-06 | E24: =ABS(D24) -> 1.6689301e-06 | F24: =E24/MAX(ABS(B24),ABS(C24),1) -> 1.0796563e-15 | G24: =IF(E24<=0.001,"Pass","Difference detected") -> Pass
A25: S19 | B25: ='SAM_73'!BW25 -> 2.337413e+09 | C25: ='SAM_73'!U79 -> 2.337413e+09 | D25: =B25-C25 -> -2.3841858e-06 | E25: =ABS(D25) -> 2.3841858e-06 | F25: =E25/MAX(ABS(B25),ABS(C25),1) -> 1.0200105e-15 | G25: =IF(E25<=0.001,"Pass","Difference detected") -> Pass
A26: S20 | B26: ='SAM_73'!BW26 -> 6.0685031e+08 | C26: ='SAM_73'!V79 -> 6.0685031e+08 | D26: =B26-C26 -> -9.5367432e-07 | E26: =ABS(D26) -> 9.5367432e-07 | F26: =E26/MAX(ABS(B26),ABS(C26),1) -> 1.5715149e-15 | G26: =IF(E26<=0.001,"Pass","Difference detected") -> Pass
A27: S21 | B27: ='SAM_73'!BW27 -> 7.4717021e+08 | C27: ='SAM_73'!W79 -> 7.4717021e+08 | D27: =B27-C27 -> -9.5367432e-07 | E27: =ABS(D27) -> 9.5367432e-07 | F27: =E27/MAX(ABS(B27),ABS(C27),1) -> 1.2763816e-15 | G27: =IF(E27<=0.001,"Pass","Difference detected") -> Pass
A28: S22 | B28: ='SAM_73'!BW28 -> 3.5617828e+08 | C28: ='SAM_73'!X79 -> 3.5617828e+08 | D28: =B28-C28 -> -5.9604645e-07 | E28: =ABS(D28) -> 5.9604645e-07 | F28: =E28/MAX(ABS(B28),ABS(C28),1) -> 1.6734497e-15 | G28: =IF(E28<=0.001,"Pass","Difference detected") -> Pass
A29: S23 | B29: ='SAM_73'!BW29 -> 2.7251797e+09 | C29: ='SAM_73'!Y79 -> 2.7251797e+09 | D29: =B29-C29 -> -3.8146973e-06 | E29: =ABS(D29) -> 3.8146973e-06 | F29: =E29/MAX(ABS(B29),ABS(C29),1) -> 1.3997966e-15 | G29: =IF(E29<=0.001,"Pass","Difference detected") -> Pass
A30: S24 | B30: ='SAM_73'!BW30 -> 85206289 | C30: ='SAM_73'!Z79 -> 85206289 | D30: =B30-C30 -> -5.9604645e-08 | E30: =ABS(D30) -> 5.9604645e-08 | F30: =E30/MAX(ABS(B30),ABS(C30),1) -> 6.995334e-16 | G30: =IF(E30<=0.001,"Pass","Difference detected") -> Pass
A31: S25 | B31: ='SAM_73'!BW31 -> 5.1106682e+08 | C31: ='SAM_73'!AA79 -> 5.1106682e+08 | D31: =B31-C31 -> -6.5565109e-07 | E31: =ABS(D31) -> 6.5565109e-07 | F31: =E31/MAX(ABS(B31),ABS(C31),1) -> 1.2829068e-15 | G31: =IF(E31<=0.001,"Pass","Difference detected") -> Pass
A32: S26 | B32: ='SAM_73'!BW32 -> 4.825169e+09 | C32: ='SAM_73'!AB79 -> 4.825169e+09 | D32: =B32-C32 -> -1.9073486e-06 | E32: =ABS(D32) -> 1.9073486e-06 | F32: =E32/MAX(ABS(B32),ABS(C32),1) -> 3.9529157e-16 | G32: =IF(E32<=0.001,"Pass","Difference detected") -> Pass
A33: S27 | B33: ='SAM_73'!BW33 -> 9.6749807e+08 | C33: ='SAM_73'!AC79 -> 9.6749807e+08 | D33: =B33-C33 -> -4.7683716e-07 | E33: =ABS(D33) -> 4.7683716e-07 | F33: =E33/MAX(ABS(B33),ABS(C33),1) -> 4.9285593e-16 | G33: =IF(E33<=0.001,"Pass","Difference detected") -> Pass
A34: S28 | B34: ='SAM_73'!BW34 -> 2.7056881e+09 | C34: ='SAM_73'!AD79 -> 2.7056881e+09 | D34: =B34-C34 -> 1.9073486e-06 | E34: =ABS(D34) -> 1.9073486e-06 | F34: =E34/MAX(ABS(B34),ABS(C34),1) -> 7.0494032e-16 | G34: =IF(E34<=0.001,"Pass","Difference detected") -> Pass
A35: S29 | B35: ='SAM_73'!BW35 -> 2.2480571e+09 | C35: ='SAM_73'!AE79 -> 2.2480571e+09 | D35: =B35-C35 -> -9.5367432e-07 | E35: =ABS(D35) -> 9.5367432e-07 | F35: =E35/MAX(ABS(B35),ABS(C35),1) -> 4.2422157e-16 | G35: =IF(E35<=0.001,"Pass","Difference detected") -> Pass
A36: S30 | B36: ='SAM_73'!BW36 -> 2.6474149e+09 | C36: ='SAM_73'!AF79 -> 2.6474149e+09 | D36: =B36-C36 -> 2.3841858e-06 | E36: =ABS(D36) -> 2.3841858e-06 | F36: =E36/MAX(ABS(B36),ABS(C36),1) -> 9.0057128e-16 | G36: =IF(E36<=0.001,"Pass","Difference detected") -> Pass
A37: S31 | B37: ='SAM_73'!BW37 -> 2.7291497e+08 | C37: ='SAM_73'!AG79 -> 2.7291497e+08 | D37: =B37-C37 -> 0 | E37: =ABS(D37) -> 0 | F37: =E37/MAX(ABS(B37),ABS(C37),1) -> 0 | G37: =IF(E37<=0.001,"Pass","Difference detected") -> Pass
A38: S32 | B38: ='SAM_73'!BW38 -> 6.9940288e+08 | C38: ='SAM_73'!AH79 -> 6.9940288e+08 | D38: =B38-C38 -> -1.1920929e-07 | E38: =ABS(D38) -> 1.1920929e-07 | F38: =E38/MAX(ABS(B38),ABS(C38),1) -> 1.7044438e-16 | G38: =IF(E38<=0.001,"Pass","Difference detected") -> Pass
A39: S33 | B39: ='SAM_73'!BW39 -> 9.9137397e+08 | C39: ='SAM_73'!AI79 -> 9.9137397e+08 | D39: =B39-C39 -> -1.5497208e-06 | E39: =ABS(D39) -> 1.5497208e-06 | F39: =E39/MAX(ABS(B39),ABS(C39),1) -> 1.563205e-15 | G39: =IF(E39<=0.001,"Pass","Difference detected") -> Pass
A40: S34 | B40: ='SAM_73'!BW40 -> 1.7269172e+08 | C40: ='SAM_73'!AJ79 -> 1.7269172e+08 | D40: =B40-C40 -> -1.4901161e-07 | E40: =ABS(D40) -> 1.4901161e-07 | F40: =E40/MAX(ABS(B40),ABS(C40),1) -> 8.6287644e-16 | G40: =IF(E40<=0.001,"Pass","Difference detected") -> Pass
A41: S35 | B41: ='SAM_73'!BW41 -> 1.7222078e+09 | C41: ='SAM_73'!AK79 -> 1.7222078e+09 | D41: =B41-C41 -> -1.9073486e-06 | E41: =ABS(D41) -> 1.9073486e-06 | F41: =E41/MAX(ABS(B41),ABS(C41),1) -> 1.1075021e-15 | G41: =IF(E41<=0.001,"Pass","Difference detected") -> Pass
A42: S36 | B42: ='SAM_73'!BW42 -> 1.149649e+08 | C42: ='SAM_73'!AL79 -> 1.149649e+08 | D42: =B42-C42 -> -1.7881393e-07 | E42: =ABS(D42) -> 1.7881393e-07 | F42: =E42/MAX(ABS(B42),ABS(C42),1) -> 1.5553786e-15 | G42: =IF(E42<=0.001,"Pass","Difference detected") -> Pass
...
